<?xml version="1.0"?>
<robot name="dance_robot">
    <material name="grey">
        <color rgba="0.7 0.7 0.7 1" />
    </material>

    <material name="green">
        <color rgba="0 0.6 0 1" />
    </material>

    <material name="white">
        <color rgba = "1 1 1 1" />
    </material>

    <link name="base_link">
        <visual>
            <geometry>
                <box size="0.6096 0.6096 0.2" />
            </geometry>
            <origin xyz="0 0 0.9" rpy="0 0 0" />
            <material name="green" />
        </visual>
        <collision>
            <origin xyz="0 0 0.9" rpy="0 0 0 " />
            <geometry>
                <box size="0.6096 0.6096 0.2" />"\
            </geometry>
        </collision>
    </link>

    <link name="left_hip_link">
        <visual>
            <geometry>
                <box size="0.2286 0.1 0.1" />
            </geometry>
            <origin xyz="0.1143 0 0" rpy="0 0 0" />
            <material name="white" />
        </visual>
        <collision>
            <origin xyz="0.1143 0 0" rpy="0 0 0 " />
            <geometry>
                <box size="0.2286 0.1 0.1" />
            </geometry>
        </collision>
    </link>

    <link name="right_hip_link">
        <visual>
            <geometry>
                <box size="0.2286 0.1 0.1" />
            </geometry>
            <origin xyz="-0.1143 0 0" rpy="0 0 0" />
            <material name="white" />
        </visual>
        <collision>
            <origin xyz="-0.1143 0 0" rpy="0 0 0" />
            <geometry>
                <box size="0.2286 0.1 0.1" />
            </geometry>
        </collision>
    </link>
    
    <link name="right_knee_short">
        <visual>
            <geometry>
                <box size="0.0762 0.1 0.1" />
            </geometry>
            <origin xyz="-0.0381 0 0" rpy="0 0 0" />
            <material name="blue" />
        </visual>
        <collision>
            <origin xyz="-0.0381 0 0" rpy="0 0 0" />
            <geometry>
                <box size="0.0762 0.1 0.1" />
            </geometry>
        </collision>
    </link>

    <link name="left_knee_short">
        <visual>
            <geometry>
                <box size="0.0762 0.1 0.1" />
            </geometry>
            <origin xyz="0.0381 0 0" rpy="0 0 0" />
            <material name="blue" />
        </visual>
        <collision>
            <origin xyz="0.0381 0 0" rpy="0 0 0" />
            <geometry>
                <box size="0.0762 0.1 0.1" />
            </geometry>
        </collision>
    </link>

    <link name="left_knee_long">
        <visual>
            <geometry>
                <box size="0.05 0.1 0.9" />
            </geometry>
            <origin xyz="0.1012 0 0" rpy="0 0 0" />
            <material name="blue" />
        </visual>
        <collision>
            <origin xyz="0.1012 0 0" rpy="0 0 0" />
            <geometry>
                <box size="0.05 0.1 0.9" />
            </geometry>
        </collision>
    </link>

    <link name="right_knee_long">
        <visual>
            <geometry>
                <box size="0.05 0.1 0.9" />
            </geometry>
            <origin xyz="-0.1012 0 0" rpy="0 0 0" />
            <material name="blue" />
        </visual>
        <collision>
            <origin xyz="-0.1012 0 0" rpy="0 0 0" />
            <geometry>
                <box size="0.05 0.1 0.9" />
            </geometry>
        </collision>
    </link>

    <joint name="left_hip_yaw" type="revolute">
        <parent link="base_link" />
        <child link="left_hip_link" />
        <origin xyz="0.3048 0 0.9" rpy="0 0 0" />
        <axis xyz="0 0 1" />
        <limit lower="-3.14" upper="3.14" effort="10" velocity="3.14" />
    </joint>

    <joint name="left_hip_pitch" type="revolute">
        <parent link="left_hip_link" />
        <child link="left_knee_short" />
        <origin xyz="0.2286 0 0" rpy="1.5708 0 0" />
        <axis xyz="0 0 1" />
        <limit lower="-3.14" upper="3.14" effort="10" velocity="3.14" />
    </joint>

    <joint name="right_hip_pitch" type="revolute">
        <parent link="right_hip_link" />
        <child link="right_knee_short" />
        <origin xyz="-0.2286 0 0" rpy="1.5708 0 0" />
        <axis xyz="0 0 1" />
        <limit lower="-3.14" upper="3.14" effort="10" velocity="3.14" />
    </joint>

    <joint name="right_hip_yaw" type="revolute">
        <parent link="base_link" />
        <child link="right_hip_link" />
        <origin xyz="-0.3048 0 0.9" rpy="0 0 0" />
        <axis xyz="0 0 1" />
        <limit lower="-3.14" upper="3.14" effort="10" velocity="3.14" />
    </joint>

    <joint name="fixed_right_knee" type="fixed">
        <parent link="right_knee_short" />
        <child link="right_knee_long" />
        <origin xyz="0 -0.45 0" rpy="-1.5708 0 0" />
    </joint>

    <joint name="fixed_left_knee" type="fixed">
        <parent link="left_knee_short" />
        <child link="left_knee_long" />
        <origin xyz="0 -0.45 0" rpy="-1.5708 0 0" />
    </joint>
</robot>