<?xml version="1.0" encoding="utf-8"?>
<!-- This URDF was automatically created by SolidWorks to URDF Exporter! Originally created by Stephen Brawner (brawner@gmail.com) 
     Commit Version: 1.6.0-4-g7f85cfe  Build Version: 1.6.7995.38578
     For more information, please see http://wiki.ros.org/sw_urdf_exporter -->
<robot
  name="6_Legs_fixed">
  <link
    name="base_link">
    <inertial>
      <origin
        xyz="-2.74585246806155E-16 4.44089209850063E-16 0.128881106851671"
        rpy="0 0 0" />
      <mass
        value="22.033335501173" />
      <inertia
        ixx="0.8417129763989"
        ixy="-1.83539305948728E-15"
        ixz="1.04328143130752E-15"
        iyy="1.85632822551968"
        iyz="-5.16947595841089E-16"
        izz="2.61458422893647" />
    </inertial>
    <visual>
      <origin
        xyz="0 0 0"
        rpy="0 0 0" />
      <geometry>
        <mesh
          filename="package://6_Legs_fixed/meshes/base_link.STL" />
      </geometry>
      <material
        name="">
        <color
          rgba="0.752941176470588 0.752941176470588 0.752941176470588 1" />
      </material>
    </visual>
    <collision>
      <origin
        xyz="0 0 0"
        rpy="0 0 0" />
      <geometry>
        <mesh
          filename="package://6_Legs_fixed/meshes/base_link.STL" />
      </geometry>
    </collision>
  </link>
  <link
    name="Link_1">
    <inertial>
      <origin
        xyz="-2.77555756156289E-16 0.0193856043120518 0.00799128397049295"
        rpy="0 0 0" />
      <mass
        value="0.294565123385619" />
      <inertia
        ixx="0.00105494307880137"
        ixy="-1.38635230288521E-17"
        ixz="8.15583132799492E-18"
        iyy="0.000429285347286343"
        iyz="2.12375671938406E-05"
        izz="0.000930841228803921" />
    </inertial>
    <visual>
      <origin
        xyz="0 0 0"
        rpy="0 0 0" />
      <geometry>
        <mesh
          filename="package://6_Legs_fixed/meshes/Link_1.STL" />
      </geometry>
      <material
        name="">
        <color
          rgba="0.792156862745098 0.819607843137255 0.933333333333333 1" />
      </material>
    </visual>
    <collision>
      <origin
        xyz="0 0 0"
        rpy="0 0 0" />
      <geometry>
        <mesh
          filename="package://6_Legs_fixed/meshes/Link_1.STL" />
      </geometry>
    </collision>
  </link>
  <joint
    name="No_Joint"
    type="fixed">
    <origin
      xyz="0.317499999999999 0.144099999999999 0.0199999999999999"
      rpy="0 0 0" />
    <parent
      link="base_link" />
    <child
      link="Link_1" />
    <axis
      xyz="0 0 0" />
  </joint>
  <link
    name="Link_2_1">
    <inertial>
      <origin
        xyz="0.00440457701081298 0.133234737745357 0.0147340785494887"
        rpy="0 0 0" />
      <mass
        value="0.35463848639693" />
      <inertia
        ixx="0.0022431506995859"
        ixy="-1.43733427396489E-05"
        ixz="4.18803786744805E-06"
        iyy="0.000838300018387207"
        iyz="0.000409382102865286"
        izz="0.00195814822262964" />
    </inertial>
    <visual>
      <origin
        xyz="0 0 0"
        rpy="0 0 0" />
      <geometry>
        <mesh
          filename="package://6_Legs_fixed/meshes/Link_2_1.STL" />
      </geometry>
      <material
        name="">
        <color
          rgba="0.752941176470588 0.752941176470588 0.752941176470588 1" />
      </material>
    </visual>
    <collision>
      <origin
        xyz="0 0 0"
        rpy="0 0 0" />
      <geometry>
        <mesh
          filename="package://6_Legs_fixed/meshes/Link_2_1.STL" />
      </geometry>
    </collision>
  </link>
  <joint
    name="Joint_1"
    type="fixed">
    <origin
      xyz="-0.0030746 0.081274 0.03275"
      rpy="0 0 0" />
    <parent
      link="Link_1" />
    <child
      link="Link_2_1" />
    <axis
      xyz="0 0 0" />
  </joint>
  <link
    name="Link_2">
    <inertial>
      <origin
        xyz="0.161310305567988 -0.239853582294744 -0.00247675891911525"
        rpy="0 0 0" />
      <mass
        value="2.21151363725631" />
      <inertia
        ixx="0.0341297219781968"
        ixy="0.0255123389151366"
        ixz="0.000272334576142029"
        iyy="0.0956933397810624"
        iyz="-0.00018045052821444"
        izz="0.112972719824399" />
    </inertial>
    <visual>
      <origin
        xyz="0 0 0"
        rpy="0 0 0" />
      <geometry>
        <mesh
          filename="package://6_Legs_fixed/meshes/Link_2.STL" />
      </geometry>
      <material
        name="">
        <color
          rgba="0.792156862745098 0.819607843137255 0.933333333333333 1" />
      </material>
    </visual>
    <collision>
      <origin
        xyz="0 0 0"
        rpy="0 0 0" />
      <geometry>
        <mesh
          filename="package://6_Legs_fixed/meshes/Link_2.STL" />
      </geometry>
    </collision>
  </link>
  <joint
    name="Joint_2"
    type="fixed">
    <origin
      xyz="0.0053286 0.22355 0.035553"
      rpy="-1.5708 1.5567 1.5708" />
    <parent
      link="Link_2_1" />
    <child
      link="Link_2" />
    <axis
      xyz="0 0 0" />
  </joint>
  <link
    name="Link_1_2">
    <inertial>
      <origin
        xyz="7.78065189729364E-17 0.0193856043120519 0.00799128397049298"
        rpy="0 0 0" />
      <mass
        value="0.294565123385619" />
      <inertia
        ixx="0.00105494307880137"
        ixy="-3.59682279865432E-18"
        ixz="-1.75639343909086E-18"
        iyy="0.000429285347286344"
        iyz="2.12375671938395E-05"
        izz="0.000930841228803922" />
    </inertial>
    <visual>
      <origin
        xyz="0 0 0"
        rpy="0 0 0" />
      <geometry>
        <mesh
          filename="package://6_Legs_fixed/meshes/Link_1_2.STL" />
      </geometry>
      <material
        name="">
        <color
          rgba="0.792156862745098 0.819607843137255 0.933333333333333 1" />
      </material>
    </visual>
    <collision>
      <origin
        xyz="0 0 0"
        rpy="0 0 0" />
      <geometry>
        <mesh
          filename="package://6_Legs_fixed/meshes/Link_1_2.STL" />
      </geometry>
    </collision>
  </link>
  <joint
    name="Fixed_Joint_2"
    type="fixed">
    <origin
      xyz="0 0.1441 0.02"
      rpy="0 0 0" />
    <parent
      link="base_link" />
    <child
      link="Link_1_2" />
    <axis
      xyz="0 0 0" />
  </joint>
  <link
    name="Link_2_1_2">
    <inertial>
      <origin
        xyz="-0.00119443281923461 0.126109214219085 0.0149275647877688"
        rpy="0 0 0" />
      <mass
        value="0.354638486396931" />
      <inertia
        ixx="0.0022432977410922"
        ixy="8.13929796118913E-11"
        ixz="-2.77070816509354E-11"
        iyy="0.000838152976880902"
        iyz="0.00040940352442008"
        izz="0.00195814822262964" />
    </inertial>
    <visual>
      <origin
        xyz="0 0 0"
        rpy="0 0 0" />
      <geometry>
        <mesh
          filename="package://6_Legs_fixed/meshes/Link_2_1_2.STL" />
      </geometry>
      <material
        name="">
        <color
          rgba="0.752941176470588 0.752941176470588 0.752941176470588 1" />
      </material>
    </visual>
    <collision>
      <origin
        xyz="0 0 0"
        rpy="0 0 0" />
      <geometry>
        <mesh
          filename="package://6_Legs_fixed/meshes/Link_2_1_2.STL" />
      </geometry>
    </collision>
  </link>
  <joint
    name="Joint_1_2"
    type="fixed">
    <origin
      xyz="0.0011944 0.088406 0.032957"
      rpy="0 0 0" />
    <parent
      link="Link_1_2" />
    <child
      link="Link_2_1_2" />
    <axis
      xyz="0 0 0" />
  </joint>
  <link
    name="Link_2_2">
    <inertial>
      <origin
        xyz="0.00232819705566778 -0.00385619268525492 7.45753830105682E-09"
        rpy="0 0 0" />
      <mass
        value="0.0693204915543849" />
      <inertia
        ixx="3.56780731089416E-05"
        ixy="1.43315615772311E-08"
        ixz="-1.40975412123694E-08"
        iyy="3.56629937884206E-05"
        iyz="-8.50756239341584E-09"
        izz="1.49181504825407E-05" />
    </inertial>
    <visual>
      <origin
        xyz="0 0 0"
        rpy="0 0 0" />
      <geometry>
        <mesh
          filename="package://6_Legs_fixed/meshes/Link_2_2.STL" />
      </geometry>
      <material
        name="">
        <color
          rgba="0.752941176470588 0.752941176470588 0.752941176470588 1" />
      </material>
    </visual>
    <collision>
      <origin
        xyz="0 0 0"
        rpy="0 0 0" />
      <geometry>
        <mesh
          filename="package://6_Legs_fixed/meshes/Link_2_2.STL" />
      </geometry>
    </collision>
  </link>
  <joint
    name="Joint_2_2"
    type="fixed">
    <origin
      xyz="-0.0011944 0.2088 0.035747"
      rpy="-1.5707 1.5708 1.5709" />
    <parent
      link="Link_2_1_2" />
    <child
      link="Link_2_2" />
    <axis
      xyz="0 0 0" />
  </joint>
  <link
    name="Link_1_3">
    <inertial>
      <origin
        xyz="-0.00443938069490774 -0.0655027911560029 -0.0251587160295106"
        rpy="0 0 0" />
      <mass
        value="0.294565123385619" />
      <inertia
        ixx="0.00105494307880137"
        ixy="-2.85091557835376E-18"
        ixz="-1.95472178815993E-18"
        iyy="0.000429285347286343"
        iyz="2.12375671938393E-05"
        izz="0.000930841228803921" />
    </inertial>
    <visual>
      <origin
        xyz="0 0 0"
        rpy="0 0 0" />
      <geometry>
        <mesh
          filename="package://6_Legs_fixed/meshes/Link_1_3.STL" />
      </geometry>
      <material
        name="">
        <color
          rgba="0.792156862745098 0.819607843137255 0.933333333333333 1" />
      </material>
    </visual>
    <collision>
      <origin
        xyz="0 0 0"
        rpy="0 0 0" />
      <geometry>
        <mesh
          filename="package://6_Legs_fixed/meshes/Link_1_3.STL" />
      </geometry>
    </collision>
  </link>
  <joint
    name="Fixed_Joint_3"
    type="fixed">
    <origin
      xyz="-0.313060619305092 0.228988395468048 0.0531500000000036"
      rpy="0 0 0" />
    <parent
      link="base_link" />
    <child
      link="Link_1_3" />
    <axis
      xyz="0 0 0" />
  </joint>
  <link
    name="Link_2_1_3">
    <inertial>
      <origin
        xyz="0.129636104863769 0.0147340785494821 -0.00444014039667867"
        rpy="0 0 0" />
      <mass
        value="0.354638486396931" />
      <inertia
        ixx="0.000838152976880922"
        ixy="0.000409403524420104"
        ixz="8.13925089437219E-11"
        iyy="0.00195814822262963"
        iyz="-2.77069450750762E-11"
        izz="0.00224329774109221" />
    </inertial>
    <visual>
      <origin
        xyz="0 0 0"
        rpy="0 0 0" />
      <geometry>
        <mesh
          filename="package://6_Legs_fixed/meshes/Link_2_1_3.STL" />
      </geometry>
      <material
        name="">
        <color
          rgba="0.792156862745098 0.819607843137255 0.933333333333333 1" />
      </material>
    </visual>
    <collision>
      <origin
        xyz="0 0 0"
        rpy="0 0 0" />
      <geometry>
        <mesh
          filename="package://6_Legs_fixed/meshes/Link_2_1_3.STL" />
      </geometry>
    </collision>
  </link>
  <joint
    name="Joint_1_3"
    type="fixed">
    <origin
      xyz="0 0 0"
      rpy="1.5708 0 1.5728" />
    <parent
      link="Link_1_3" />
    <child
      link="Link_2_1_3" />
    <axis
      xyz="0 0 0" />
  </joint>
  <link
    name="Link_2_3">
    <inertial>
      <origin
        xyz="0.162625008862092 -0.24669558344667 4.49640324973188E-15"
        rpy="0 0 0" />
      <mass
        value="2.2115136372563" />
      <inertia
        ixx="0.0338513825334559"
        ixy="0.0251742141271308"
        ixz="1.2732641614774E-16"
        iyy="0.0959697941105454"
        iyz="-2.74845250725075E-17"
        izz="0.112974604939655" />
    </inertial>
    <visual>
      <origin
        xyz="0 0 0"
        rpy="0 0 0" />
      <geometry>
        <mesh
          filename="package://6_Legs_fixed/meshes/Link_2_3.STL" />
      </geometry>
      <material
        name="">
        <color
          rgba="0.792156862745098 0.819607843137255 0.933333333333333 1" />
      </material>
    </visual>
    <collision>
      <origin
        xyz="0 0 0"
        rpy="0 0 0" />
      <geometry>
        <mesh
          filename="package://6_Legs_fixed/meshes/Link_2_3.STL" />
      </geometry>
    </collision>
  </link>
  <joint
    name="Joint_2_3"
    type="fixed">
    <origin
      xyz="0.2123 0.035495 -0.0044401"
      rpy="-3.1416 0 -1.5752" />
    <parent
      link="Link_2_1_3" />
    <child
      link="Link_2_3" />
    <axis
      xyz="0 0 0" />
  </joint>
  <link
    name="Link_1_4">
    <inertial>
      <origin
        xyz="-3.33066907387547E-16 -0.019385604312052 0.00799128397049301"
        rpy="0 0 0" />
      <mass
        value="0.29456512338562" />
      <inertia
        ixx="0.00105494307880138"
        ixy="-1.13716178449994E-17"
        ixz="1.29412240558589E-18"
        iyy="0.000429285347286344"
        iyz="-2.12375671938404E-05"
        izz="0.000930841228803925" />
    </inertial>
    <visual>
      <origin
        xyz="0 0 0"
        rpy="0 0 0" />
      <geometry>
        <mesh
          filename="package://6_Legs_fixed/meshes/Link_1_4.STL" />
      </geometry>
      <material
        name="">
        <color
          rgba="0.792156862745098 0.819607843137255 0.933333333333333 1" />
      </material>
    </visual>
    <collision>
      <origin
        xyz="0 0 0"
        rpy="0 0 0" />
      <geometry>
        <mesh
          filename="package://6_Legs_fixed/meshes/Link_1_4.STL" />
      </geometry>
    </collision>
  </link>
  <joint
    name="Fixed_Joint_4"
    type="fixed">
    <origin
      xyz="0.317500000000001 -0.144099999999999 0.02"
      rpy="0 0 0" />
    <parent
      link="base_link" />
    <child
      link="Link_1_4" />
    <axis
      xyz="0 0 0" />
  </joint>
  <link
    name="Link_2_1_4">
    <inertial>
      <origin
        xyz="0.125562950483786 0.001689160065936 0.014734078549491"
        rpy="0 0 0" />
      <mass
        value="0.35463848639693" />
      <inertia
        ixx="0.000838310778854466"
        ixy="-1.48899199282642E-05"
        ixz="0.00040938053511016"
        iyy="0.00224313993911864"
        iyz="4.33858047185253E-06"
        izz="0.00195814822262963" />
    </inertial>
    <visual>
      <origin
        xyz="0 0 0"
        rpy="0 0 0" />
      <geometry>
        <mesh
          filename="package://6_Legs_fixed/meshes/Link_2_1_4.STL" />
      </geometry>
      <material
        name="">
        <color
          rgba="0.752941176470588 0.752941176470588 0.752941176470588 1" />
      </material>
    </visual>
    <collision>
      <origin
        xyz="0 0 0"
        rpy="0 0 0" />
      <geometry>
        <mesh
          filename="package://6_Legs_fixed/meshes/Link_2_1_4.STL" />
      </geometry>
    </collision>
  </link>
  <joint
    name="Joint_1_4"
    type="continuous">
    <origin
      xyz="-0.00031135 -0.088945 0.03315"
      rpy="0 0 -1.5708" />
    <parent
      link="Link_1_4" />
    <child
      link="Link_2_1_4" />
    <axis
      xyz="0 0 -1" />
  </joint>
  <link
    name="Link_2_4">
    <inertial>
      <origin
        xyz="0.162625008862141 0.238963561713091 -0.00253231568323709"
        rpy="0 0 0" />
      <mass
        value="2.21151363725629" />
      <inertia
        ixx="0.0338513825334561"
        ixy="-0.0251728007382378"
        ixz="0.000266758151926227"
        iyy="0.0959717035036993"
        iyz="0.000180181085593333"
        izz="0.112972695546501" />
    </inertial>
    <visual>
      <origin
        xyz="0 0 0"
        rpy="0 0 0" />
      <geometry>
        <mesh
          filename="package://6_Legs_fixed/meshes/Link_2_4.STL" />
      </geometry>
      <material
        name="">
        <color
          rgba="0.792156862745098 0.819607843137255 0.933333333333333 1" />
      </material>
    </visual>
    <collision>
      <origin
        xyz="0 0 0"
        rpy="0 0 0" />
      <geometry>
        <mesh
          filename="package://6_Legs_fixed/meshes/Link_2_4.STL" />
      </geometry>
    </collision>
  </link>
  <joint
    name="Joint_2_4"
    type="fixed">
    <origin
      xyz="0.21595 0.0026471 0.035432"
      rpy="-1.5602 1.5587 -3.131" />
    <parent
      link="Link_2_1_4" />
    <child
      link="Link_2_4" />
    <axis
      xyz="0 0 0" />
  </joint>
  <link
    name="Link_1_5">
    <inertial>
      <origin
        xyz="-3.93318232140555E-17 -0.0193856043120521 0.00799128397049298"
        rpy="0 0 0" />
      <mass
        value="0.294565123385619" />
      <inertia
        ixx="0.00105494307880137"
        ixy="-8.56216411872192E-19"
        ixz="2.04207351117204E-18"
        iyy="0.000429285347286344"
        iyz="-2.12375671938402E-05"
        izz="0.000930841228803922" />
    </inertial>
    <visual>
      <origin
        xyz="0 0 0"
        rpy="0 0 0" />
      <geometry>
        <mesh
          filename="package://6_Legs_fixed/meshes/Link_1_5.STL" />
      </geometry>
      <material
        name="">
        <color
          rgba="0.792156862745098 0.819607843137255 0.933333333333333 1" />
      </material>
    </visual>
    <collision>
      <origin
        xyz="0 0 0"
        rpy="0 0 0" />
      <geometry>
        <mesh
          filename="package://6_Legs_fixed/meshes/Link_1_5.STL" />
      </geometry>
    </collision>
  </link>
  <joint
    name="Fixed_Joint_5"
    type="fixed">
    <origin
      xyz="0 -0.144099999999999 0.02"
      rpy="0 0 0" />
    <parent
      link="base_link" />
    <child
      link="Link_1_5" />
    <axis
      xyz="0 0 0" />
  </joint>
  <link
    name="Link_2_1_5">
    <inertial>
      <origin
        xyz="0.126045120861653 0.0147340785494941 0.00202323068990402"
        rpy="0 0 0" />
      <mass
        value="0.354638486396932" />
      <inertia
        ixx="0.000838152976880909"
        ixy="0.000409403524420088"
        ixz="8.13925102230601E-11"
        iyy="0.00195814822262964"
        iyz="-2.77069452828193E-11"
        izz="0.00224329774109221" />
    </inertial>
    <visual>
      <origin
        xyz="0 0 0"
        rpy="0 0 0" />
      <geometry>
        <mesh
          filename="package://6_Legs_fixed/meshes/Link_2_1_5.STL" />
      </geometry>
      <material
        name="">
        <color
          rgba="0.792156862745098 0.819607843137255 0.933333333333333 1" />
      </material>
    </visual>
    <collision>
      <origin
        xyz="0 0 0"
        rpy="0 0 0" />
      <geometry>
        <mesh
          filename="package://6_Legs_fixed/meshes/Link_2_1_5.STL" />
      </geometry>
    </collision>
  </link>
  <joint
    name="Joint_1_5"
    type="continuous">
    <origin
      xyz="0.0020232 -0.088471 0.03315"
      rpy="1.5708 0 -1.5708" />
    <parent
      link="Link_1_5" />
    <child
      link="Link_2_1_5" />
    <axis
      xyz="0 -1 0" />
  </joint>
  <link
    name="Link_2_5">
    <inertial>
      <origin
        xyz="0.153070378325338 0.252338289947187 -0.318404551408"
        rpy="0 0 0" />
      <mass
        value="2.21151363725631" />
      <inertia
        ixx="0.0350279836952742"
        ixy="-0.0265601829836423"
        ixz="4.41590441039777E-05"
        iyy="0.0947932537385775"
        iyz="3.31202719611275E-05"
        izz="0.112974544149805" />
    </inertial>
    <visual>
      <origin
        xyz="0 0 0"
        rpy="0 0 0" />
      <geometry>
        <mesh
          filename="package://6_Legs_fixed/meshes/Link_2_5.STL" />
      </geometry>
      <material
        name="">
        <color
          rgba="0.792156862745098 0.819607843137255 0.933333333333333 1" />
      </material>
    </visual>
    <collision>
      <origin
        xyz="0 0 0"
        rpy="0 0 0" />
      <geometry>
        <mesh
          filename="package://6_Legs_fixed/meshes/Link_2_5.STL" />
      </geometry>
    </collision>
  </link>
  <joint
    name="Joint_2_5"
    type="fixed">
    <origin
      xyz="0.20841 0.031615 0.31994"
      rpy="0.0019793 0.00010792 -1.6253" />
    <parent
      link="Link_2_1_5" />
    <child
      link="Link_2_5" />
    <axis
      xyz="0 0 0" />
  </joint>
  <link
    name="Link_1_6">
    <inertial>
      <origin
        xyz="-5.55111512312578E-17 -0.0193856043120519 0.00799128397049298"
        rpy="0 0 0" />
      <mass
        value="0.294565123385619" />
      <inertia
        ixx="0.00105494307880137"
        ixy="-1.42008686409587E-18"
        ixz="2.24120531308849E-18"
        iyy="0.000429285347286344"
        iyz="-2.12375671938401E-05"
        izz="0.000930841228803922" />
    </inertial>
    <visual>
      <origin
        xyz="0 0 0"
        rpy="0 0 0" />
      <geometry>
        <mesh
          filename="package://6_Legs_fixed/meshes/Link_1_6.STL" />
      </geometry>
      <material
        name="">
        <color
          rgba="0.792156862745098 0.819607843137255 0.933333333333333 1" />
      </material>
    </visual>
    <collision>
      <origin
        xyz="0 0 0"
        rpy="0 0 0" />
      <geometry>
        <mesh
          filename="package://6_Legs_fixed/meshes/Link_1_6.STL" />
      </geometry>
    </collision>
  </link>
  <joint
    name="Fixed_Joint_6"
    type="fixed">
    <origin
      xyz="-0.317499999999991 -0.144100000000011 0.02"
      rpy="0 0 0" />
    <parent
      link="base_link" />
    <child
      link="Link_1_6" />
    <axis
      xyz="0 0 0" />
  </joint>
  <link
    name="Link_2_1_6">
    <inertial>
      <origin
        xyz="0.130403839661595 -0.00469710591727718 0.0147340785494955"
        rpy="0 0 0" />
      <mass
        value="0.354638486396932" />
      <inertia
        ixx="0.00083815849782033"
        ixy="2.78526275964138E-06"
        ixz="0.000409402720135687"
        iyy="0.0022432922201528"
        iyz="-8.11512841643623E-07"
        izz="0.00195814822262964" />
    </inertial>
    <visual>
      <origin
        xyz="0 0 0"
        rpy="0 0 0" />
      <geometry>
        <mesh
          filename="package://6_Legs_fixed/meshes/Link_2_1_6.STL" />
      </geometry>
      <material
        name="">
        <color
          rgba="0.752941176470588 0.752941176470588 0.752941176470588 1" />
      </material>
    </visual>
    <collision>
      <origin
        xyz="0 0 0"
        rpy="0 0 0" />
      <geometry>
        <mesh
          filename="package://6_Legs_fixed/meshes/Link_2_1_6.STL" />
      </geometry>
    </collision>
  </link>
  <joint
    name="Joint_1_6"
    type="continuous">
    <origin
      xyz="0.0044394 -0.084112 0.03315"
      rpy="0 0 -1.5708" />
    <parent
      link="Link_1_6" />
    <child
      link="Link_2_1_6" />
    <axis
      xyz="0 0 -1" />
  </joint>
  <link
    name="Link_2_6">
    <inertial>
      <origin
        xyz="0.160396839658805 -0.252836281178716 -0.0639999999999995"
        rpy="0 0 0" />
      <mass
        value="2.21151363725629" />
      <inertia
        ixx="0.033851382533456"
        ixy="0.0251742141271309"
        ixz="-1.77991268371282E-16"
        iyy="0.0959697941105456"
        iyz="4.72983197746801E-17"
        izz="0.112974604939655" />
    </inertial>
    <visual>
      <origin
        xyz="0 0 0"
        rpy="0 0 0" />
      <geometry>
        <mesh
          filename="package://6_Legs_fixed/meshes/Link_2_6.STL" />
      </geometry>
      <material
        name="">
        <color
          rgba="0.792156862745098 0.819607843137255 0.933333333333333 1" />
      </material>
    </visual>
    <collision>
      <origin
        xyz="0 0 0"
        rpy="0 0 0" />
      <geometry>
        <mesh
          filename="package://6_Legs_fixed/meshes/Link_2_6.STL" />
      </geometry>
    </collision>
  </link>
  <joint
    name="Joint_2_6"
    type="fixed">
    <origin
      xyz="0.20954 0.059146 0.033542"
      rpy="1.5708 1.5163 3.1396" />
    <parent
      link="Link_2_1_6" />
    <child
      link="Link_2_6" />
    <axis
      xyz="0 0 0" />
  </joint>
</robot>